File: Specimen_RawData_1.csv
Strain : Tensile strain (Extension) gauge length,"100.00000",mm

Time,Extension,Load
(s),(mm),(N)
"0.00000","0.00000","-0.00004"
"1.00000","-0.03316","-0.00007"
"2.00000","-0.06600","-0.00019"
"3.00000","-0.09906","-0.00035"
"4.00000","-0.13218","-0.00029"
"5.00000","-0.16528","-0.00060"
"6.00000","-0.19810","-0.00056"
"7.00000","-0.23102","-0.00069"
"8.00000","-0.26408","-0.00075"
"9.00000","-0.29716","-0.00093"
"10.00000","-0.33020","-0.00107"
"11.00000","-0.36318","-0.00133"
"12.00000","-0.39624","-0.00140"
"13.00000","-0.42928","-0.00177"
"14.00000","-0.46228","-0.00184"
"14.99500","-0.49502","-0.00220"
"15.89600","-0.49492","-0.00196"
"16.89600","-0.49488","-0.00192"
"17.89600","-0.49490","-0.00172"
"18.89600","-0.49490","-0.00172"
"19.89600","-0.49490","-0.00170"
"20.89600","-0.49490","-0.00178"
"21.89600","-0.49490","-0.00167"
"22.89600","-0.49490","-0.00171"
"23.89600","-0.49490","-0.00162"
"24.89600","-0.49490","-0.00145"
"25.89600","-0.49490","-0.00155"
"26.89600","-0.49490","-0.00147"
"27.89600","-0.49492","-0.00154"
"28.89600","-0.49492","-0.00143"
"29.89600","-0.49492","-0.00147"
"30.89600","-0.49492","-0.00139"
"31.89600","-0.49492","-0.00152"
"32.89600","-0.49492","-0.00156"
"33.89600","-0.49492","-0.00149"
"34.89600","-0.49492","-0.00134"
"35.89600","-0.49492","-0.00139"
"36.89600","-0.49492","-0.00125"
"37.89600","-0.49492","-0.00134"
"38.89600","-0.49492","-0.00143"
"39.89600","-0.49492","-0.00140"
"40.89600","-0.49492","-0.00144"
"41.89600","-0.49492","-0.00140"
"42.89600","-0.49492","-0.00131"
"43.89600","-0.49492","-0.00133"
"44.89600","-0.49492","-0.00131"
"45.89600","-0.49492","-0.00123"
"46.89600","-0.49492","-0.00139"
"47.89600","-0.49492","-0.00124"
"48.89600","-0.49492","-0.00136"
"49.89600","-0.49492","-0.00135"
"50.89600","-0.49492","-0.00146"
"51.89600","-0.49492","-0.00122"
"52.89600","-0.49492","-0.00133"
"53.89600","-0.49492","-0.00125"
"54.89600","-0.49492","-0.00128"
"55.89600","-0.49492","-0.00128"
"56.89600","-0.49492","-0.00143"
"57.89600","-0.49492","-0.00131"
"58.89600","-0.49492","-0.00132"
"59.89600","-0.49492","-0.00128"
"60.89600","-0.49492","-0.00125"
"61.89600","-0.49492","-0.00118"
"62.89600","-0.49492","-0.00114"
"63.89600","-0.49492","-0.00121"
"64.89600","-0.49492","-0.00127"
"65.89600","-0.49492","-0.00134"
"66.89600","-0.49492","-0.00129"
"67.89600","-0.49492","-0.00143"
"68.89600","-0.49492","-0.00122"
"69.89600","-0.49492","-0.00129"
"70.89600","-0.49492","-0.00111"
"71.89600","-0.49492","-0.00130"
"72.89600","-0.49492","-0.00118"
"73.89600","-0.49492","-0.00118"
"74.89600","-0.49492","-0.00114"
"75.89600","-0.49492","-0.00128"
"76.89600","-0.49492","-0.00134"
"77.89600","-0.49492","-0.00125"
"78.89600","-0.49492","-0.00119"
"79.89600","-0.49492","-0.00120"
"80.89600","-0.49492","-0.00121"
"81.89600","-0.49492","-0.00110"
"82.89600","-0.49492","-0.00128"
"83.89600","-0.49492","-0.00116"
"84.89600","-0.49492","-0.00122"
"85.89600","-0.49492","-0.00115"
"86.89600","-0.49492","-0.00117"
"87.89600","-0.49492","-0.00120"
"88.89600","-0.49492","-0.00127"
"89.89600","-0.49492","-0.00119"
"90.89600","-0.49492","-0.00113"
"91.89600","-0.49492","-0.00115"
"92.89600","-0.49492","-0.00123"
"93.89600","-0.49492","-0.00118"
"94.89600","-0.49492","-0.00114"
"95.89600","-0.49492","-0.00126"
"96.89600","-0.49492","-0.00123"
"97.89600","-0.49492","-0.00107"
"98.89600","-0.49492","-0.00116"
"99.89600","-0.49492","-0.00116"
"100.89600","-0.49492","-0.00113"
"101.89600","-0.49492","-0.00120"
"102.89600","-0.49492","-0.00114"
"103.89600","-0.49492","-0.00127"
"104.89600","-0.49492","-0.00114"
"105.89600","-0.49492","-0.00115"
"106.89600","-0.49492","-0.00114"
"107.89600","-0.49492","-0.00111"
"108.89600","-0.49492","-0.00118"
"109.89600","-0.49492","-0.00116"
"110.89600","-0.49492","-0.00127"
"111.89600","-0.49492","-0.00116"
"112.89600","-0.49492","-0.00121"
"113.89600","-0.49492","-0.00119"
"114.89600","-0.49492","-0.00118"
"115.89600","-0.49492","-0.00110"
"116.89600","-0.49492","-0.00110"
"117.89600","-0.49492","-0.00111"
"118.89600","-0.49492","-0.00115"
"119.89600","-0.49492","-0.00115"
"120.89600","-0.49492","-0.00120"
"121.89600","-0.49492","-0.00116"
"122.89600","-0.49492","-0.00123"
"123.89600","-0.49492","-0.00116"
"124.89600","-0.49492","-0.00111"
"125.89600","-0.49492","-0.00111"
"126.89600","-0.49492","-0.00130"
"127.89600","-0.49492","-0.00115"
"128.89600","-0.49492","-0.00119"
"129.89600","-0.49492","-0.00109"
"130.89600","-0.49492","-0.00117"
"131.89600","-0.49492","-0.00118"
"132.89600","-0.49492","-0.00109"
"133.89600","-0.49492","-0.00118"
"134.89600","-0.49492","-0.00113"
"135.89600","-0.49492","-0.00112"
"136.89600","-0.49492","-0.00124"
"137.89600","-0.49492","-0.00124"
"138.89600","-0.49492","-0.00112"
"139.89600","-0.49492","-0.00115"
"140.89600","-0.49492","-0.00113"
"141.89600","-0.49492","-0.00120"
"142.89600","-0.49492","-0.00096"
"143.89600","-0.49492","-0.00110"
"144.89600","-0.49492","-0.00116"
"145.89600","-0.49492","-0.00121"
"146.89600","-0.49492","-0.00109"
"147.89600","-0.49492","-0.00122"
"148.89600","-0.49492","-0.00102"
"149.89600","-0.49492","-0.00113"
"150.89600","-0.49492","-0.00098"
"151.89600","-0.49492","-0.00121"
"152.89600","-0.49492","-0.00104"
"153.89600","-0.49492","-0.00121"
"154.89600","-0.49492","-0.00124"
"155.89600","-0.49492","-0.00122"
"156.89600","-0.49492","-0.00106"
"157.89600","-0.49492","-0.00128"
"158.89600","-0.49492","-0.00098"
"159.89600","-0.49492","-0.00110"
"160.89600","-0.49492","-0.00118"
"161.89600","-0.49492","-0.00123"
"162.89600","-0.49492","-0.00111"
"163.89600","-0.49492","-0.00113"
"164.89600","-0.49492","-0.00106"
"165.89600","-0.49492","-0.00102"
"166.89600","-0.49492","-0.00103"
"167.89600","-0.49492","-0.00116"
"168.89600","-0.49492","-0.00102"
"169.89600","-0.49492","-0.00123"
"170.89600","-0.49492","-0.00115"
"171.89600","-0.49492","-0.00112"
"172.89600","-0.49492","-0.00108"
"173.89600","-0.49492","-0.00097"
"174.89600","-0.49492","-0.00101"
"175.89600","-0.49492","-0.00107"
"176.89600","-0.49492","-0.00109"
"177.89600","-0.49492","-0.00110"
"178.89600","-0.49492","-0.00113"
"179.89600","-0.49492","-0.00108"
"180.89600","-0.49492","-0.00115"
"181.89600","-0.49492","-0.00099"
"182.89600","-0.49492","-0.00110"
"183.89600","-0.49492","-0.00101"
"184.89600","-0.49492","-0.00102"
"185.89600","-0.49492","-0.00108"
"186.89600","-0.49492","-0.00112"
"187.89600","-0.49492","-0.00104"
"188.89600","-0.49492","-0.00114"
"189.89600","-0.49492","-0.00099"
"190.89600","-0.49492","-0.00108"
"191.89600","-0.49492","-0.00097"
"192.89600","-0.49492","-0.00109"
"193.89600","-0.49492","-0.00111"
"194.89600","-0.49492","-0.00103"
"195.89600","-0.49492","-0.00116"
"196.89600","-0.49492","-0.00119"
"197.89600","-0.49492","-0.00099"
"198.89600","-0.49492","-0.00098"
"199.89600","-0.49492","-0.00099"
"200.89600","-0.49492","-0.00101"
"201.89600","-0.49492","-0.00105"
"202.89600","-0.49492","-0.00106"
"203.89600","-0.49492","-0.00117"
"204.89600","-0.49492","-0.00108"
"205.89600","-0.49492","-0.00105"
"206.89600","-0.49492","-0.00096"
"207.89600","-0.49492","-0.00100"
"208.89600","-0.49492","-0.00103"
"209.89600","-0.49492","-0.00110"
"210.89600","-0.49492","-0.00109"
"211.89600","-0.49492","-0.00105"
"212.89600","-0.49492","-0.00112"
"213.89600","-0.49492","-0.00101"
"214.89600","-0.49492","-0.00102"
"215.89600","-0.49492","-0.00098"
"216.89600","-0.49492","-0.00106"
"217.89600","-0.49492","-0.00101"
"218.89600","-0.49492","-0.00105"
"219.89600","-0.49492","-0.00109"
"220.89600","-0.49492","-0.00106"
"221.89600","-0.49492","-0.00100"
"222.89600","-0.49492","-0.00108"
"223.89600","-0.49492","-0.00103"
"224.89600","-0.49492","-0.00099"
"225.89600","-0.49492","-0.00102"
"226.89600","-0.49492","-0.00109"
"227.89600","-0.49492","-0.00111"
"228.89600","-0.49492","-0.00100"
"229.89600","-0.49492","-0.00106"
"230.89600","-0.49492","-0.00105"
"231.89600","-0.49492","-0.00095"
"232.89600","-0.49492","-0.00091"
"233.89600","-0.49492","-0.00095"
"234.89600","-0.49492","-0.00105"
"235.89600","-0.49492","-0.00104"
"236.89600","-0.49492","-0.00101"
"237.89600","-0.49492","-0.00104"
"238.89600","-0.49492","-0.00091"
"239.89600","-0.49492","-0.00099"
"240.89600","-0.49492","-0.00102"
"241.89600","-0.49492","-0.00098"
"242.89600","-0.49492","-0.00112"
"243.89600","-0.49492","-0.00091"
"244.89600","-0.49492","-0.00089"
"245.89600","-0.49492","-0.00111"
"246.89600","-0.49492","-0.00099"
"247.89600","-0.49492","-0.00096"
"248.89600","-0.49492","-0.00094"
"249.89600","-0.49494","-0.00102"
"250.89600","-0.49492","-0.00105"
"251.89600","-0.49492","-0.00085"
"252.89600","-0.49492","-0.00093"
"253.89600","-0.49492","-0.00102"
"254.89600","-0.49492","-0.00093"
"255.79700","-0.52010","-0.00147"
"256.79700","-0.55320","-0.00214"
"257.79700","-0.58620","-0.00252"
"258.79700","-0.61926","-0.00312"
"259.79700","-0.65228","-0.00350"
"260.79700","-0.68530","-0.00417"
"261.79700","-0.71818","-0.00491"
"262.79700","-0.75120","-0.00578"
"263.79700","-0.78422","-0.00673"
"264.79700","-0.81728","-0.00805"
"265.79700","-0.85008","-0.00934"
"266.79700","-0.88332","-0.01099"
"267.79700","-0.91626","-0.01291"
"268.79700","-0.94932","-0.01529"
"269.79700","-0.98218","-0.01793"
"270.63000","-0.99014","-0.01624"
"271.63000","-0.98994","-0.01479"
"272.63000","-0.98994","-0.01398"
"273.63000","-0.98996","-0.01332"
"274.63000","-0.98996","-0.01290"
"275.63000","-0.98996","-0.01251"
"276.63000","-0.98996","-0.01234"
"277.63000","-0.98996","-0.01202"
"278.63000","-0.98996","-0.01174"
"279.63000","-0.98996","-0.01148"
"280.63000","-0.98996","-0.01123"
"281.63000","-0.98996","-0.01096"
"282.63000","-0.98996","-0.01088"
"283.63000","-0.98996","-0.01074"
"284.63000","-0.98996","-0.01061"
"285.63000","-0.98996","-0.01039"
"286.63000","-0.98996","-0.01033"
"287.63000","-0.98996","-0.01015"
"288.63000","-0.98996","-0.01003"
"289.63000","-0.98996","-0.00988"
"290.63000","-0.98996","-0.00974"
"291.63000","-0.98996","-0.00970"
"292.63000","-0.98996","-0.00962"
"293.63000","-0.98996","-0.00958"
"294.63000","-0.98996","-0.00947"
"295.63000","-0.98996","-0.00938"
"296.63000","-0.98996","-0.00931"
"297.63000","-0.98996","-0.00911"
"298.63000","-0.98996","-0.00907"
"299.63000","-0.98996","-0.00894"
"300.63000","-0.98996","-0.00892"
"301.63000","-0.98996","-0.00877"
"302.63000","-0.98996","-0.00873"
"303.63000","-0.98996","-0.00873"
"304.63000","-0.98996","-0.00870"
"305.63000","-0.98996","-0.00861"
"306.63000","-0.98996","-0.00854"
"307.63000","-0.98996","-0.00847"
"308.63000","-0.98996","-0.00850"
"309.63000","-0.98996","-0.00834"
"310.63000","-0.98996","-0.00840"
"311.63000","-0.98996","-0.00822"
"312.63000","-0.98996","-0.00829"
"313.63000","-0.98996","-0.00812"
"314.63000","-0.98996","-0.00817"
"315.63000","-0.98996","-0.00811"
"316.63000","-0.98996","-0.00799"
"317.63000","-0.98996","-0.00790"
"318.63000","-0.98996","-0.00797"
"319.63000","-0.98996","-0.00788"
"320.63000","-0.98996","-0.00789"
"321.63000","-0.98996","-0.00797"
"322.63000","-0.98996","-0.00775"
"323.63000","-0.98996","-0.00775"
"324.63000","-0.98996","-0.00760"
"325.63000","-0.98996","-0.00762"
"326.63000","-0.98996","-0.00750"
"327.63000","-0.98996","-0.00760"
"328.63000","-0.98996","-0.00745"
"329.63000","-0.98996","-0.00751"
"330.63000","-0.98996","-0.00749"
"331.63000","-0.98996","-0.00752"
"332.63000","-0.98996","-0.00735"
"333.63000","-0.98996","-0.00746"
"334.63000","-0.98998","-0.00730"
"335.63000","-0.98998","-0.00727"
"336.63000","-0.98998","-0.00717"
"337.63000","-0.98998","-0.00730"
"338.63000","-0.98998","-0.00724"
"339.63000","-0.98998","-0.00720"
"340.63000","-0.98998","-0.00713"
"341.63000","-0.98998","-0.00719"
"342.63000","-0.98998","-0.00719"
"343.63000","-0.98998","-0.00695"
"344.63000","-0.98998","-0.00702"
"345.63000","-0.98998","-0.00705"
"346.63000","-0.98998","-0.00702"
"347.63000","-0.98998","-0.00696"
"348.63000","-0.98998","-0.00704"
"349.63000","-0.98998","-0.00699"
"350.63000","-0.98998","-0.00694"
"351.63000","-0.98998","-0.00679"
"352.63000","-0.98998","-0.00681"
"353.63000","-0.98998","-0.00677"
"354.63000","-0.98998","-0.00683"
"355.63000","-0.98998","-0.00681"
"356.63000","-0.98998","-0.00683"
"357.63000","-0.98998","-0.00665"
"358.63000","-0.98998","-0.00666"
"359.63000","-0.98998","-0.00663"
"360.63000","-0.98998","-0.00662"
"361.63000","-0.98998","-0.00658"
"362.63000","-0.98998","-0.00664"
"363.63000","-0.98998","-0.00652"
"364.63000","-0.98998","-0.00661"
"365.63000","-0.98998","-0.00653"
"366.63000","-0.98998","-0.00661"
"367.63000","-0.98998","-0.00647"
"368.63000","-0.98998","-0.00647"
"369.63000","-0.98998","-0.00645"
"370.63000","-0.98998","-0.00641"
"371.63000","-0.98998","-0.00647"
"372.63000","-0.98998","-0.00634"
"373.63000","-0.98998","-0.00638"
"374.63000","-0.98998","-0.00637"
"375.63000","-0.98998","-0.00634"
"376.63000","-0.98998","-0.00634"
"377.63000","-0.98998","-0.00644"
"378.63000","-0.98998","-0.00623"
"379.63000","-0.98998","-0.00627"
"380.63000","-0.98998","-0.00624"
"381.63000","-0.98998","-0.00623"
"382.63000","-0.98998","-0.00623"
"383.63000","-0.98998","-0.00625"
"384.63000","-0.98998","-0.00634"
"385.63000","-0.98998","-0.00619"
"386.63000","-0.98998","-0.00617"
"387.63000","-0.98998","-0.00612"
"388.63000","-0.98998","-0.00624"
"389.63000","-0.98998","-0.00611"
"390.63000","-0.98998","-0.00605"
"391.63000","-0.98998","-0.00618"
"392.63000","-0.98998","-0.00613"
"393.63000","-0.98998","-0.00618"
"394.63000","-0.98998","-0.00603"
"395.63000","-0.98998","-0.00617"
"396.63000","-0.98998","-0.00597"
"397.63000","-0.98998","-0.00599"
"398.63000","-0.98998","-0.00604"
"399.63000","-0.98998","-0.00610"
"400.63000","-0.98998","-0.00598"
"401.63000","-0.98998","-0.00597"
"402.63000","-0.98998","-0.00601"
"403.63000","-0.98998","-0.00595"
"404.63000","-0.98998","-0.00583"
"405.63000","-0.98998","-0.00590"
"406.63000","-0.98998","-0.00588"
"407.63000","-0.98998","-0.00593"
"408.63000","-0.98998","-0.00592"
"409.63000","-0.98998","-0.00594"
"410.63000","-0.98998","-0.00590"
"411.63000","-0.98998","-0.00596"
"412.63000","-0.98998","-0.00585"
"413.63000","-0.98998","-0.00588"
"414.63000","-0.98998","-0.00570"
"415.63000","-0.98998","-0.00574"
"416.63000","-0.98998","-0.00576"
"417.63000","-0.98998","-0.00593"
"418.63000","-0.98998","-0.00579"
"419.63000","-0.98998","-0.00572"
"420.63000","-0.98998","-0.00571"
"421.63000","-0.98998","-0.00579"
"422.63000","-0.98998","-0.00570"
"423.63000","-0.98998","-0.00565"
"424.63000","-0.98998","-0.00576"
"425.63000","-0.98998","-0.00576"
"426.63000","-0.98998","-0.00575"
"427.63000","-0.98998","-0.00559"
"428.63000","-0.98998","-0.00580"
"429.63000","-0.98998","-0.00560"
"430.63000","-0.98998","-0.00567"
"431.63000","-0.98998","-0.00547"
"432.63000","-0.98998","-0.00567"
"433.63000","-0.98998","-0.00546"
"434.63000","-0.98998","-0.00576"
"435.63000","-0.98998","-0.00557"
"436.63000","-0.98998","-0.00568"
"437.63000","-0.98998","-0.00554"
"438.63000","-0.98998","-0.00555"
"439.63000","-0.98998","-0.00556"
"440.63000","-0.98998","-0.00564"
"441.63000","-0.98998","-0.00559"
"442.63000","-0.98998","-0.00549"
"443.63000","-0.98998","-0.00555"
"444.63000","-0.98998","-0.00554"
"445.63000","-0.98998","-0.00546"
"446.63000","-0.98998","-0.00557"
"447.63000","-0.98998","-0.00543"
"448.63000","-0.98998","-0.00536"
"449.63000","-0.98998","-0.00548"
"450.63000","-0.98998","-0.00536"
"451.63000","-0.98998","-0.00552"
"452.63000","-0.98998","-0.00546"
"453.63000","-0.98998","-0.00549"
"454.63000","-0.98998","-0.00543"
"455.63000","-0.98998","-0.00539"
"456.63000","-0.98998","-0.00530"
"457.63000","-0.98998","-0.00537"
"458.63000","-0.98998","-0.00536"
"459.63000","-0.98998","-0.00553"
"460.63000","-0.98998","-0.00530"
"461.63000","-0.98998","-0.00537"
"462.63000","-0.98998","-0.00529"
"463.63000","-0.98998","-0.00531"
"464.63000","-0.98998","-0.00517"
"465.63000","-0.98998","-0.00534"
"466.63000","-0.98998","-0.00531"
"467.63000","-0.98998","-0.00541"
"468.63000","-0.98998","-0.00522"
"469.63000","-0.98998","-0.00537"
"470.63000","-0.98998","-0.00535"
"471.63000","-0.98998","-0.00529"
"472.63000","-0.98998","-0.00521"
"473.63000","-0.98998","-0.00525"
"474.63000","-0.98998","-0.00519"
"475.63000","-0.98998","-0.00520"
"476.63000","-0.98998","-0.00522"
"477.63000","-0.98998","-0.00521"
"478.63000","-0.98998","-0.00531"
"479.63000","-0.98998","-0.00505"
"480.63000","-0.98998","-0.00521"
"481.63000","-0.98998","-0.00514"
"482.63000","-0.98998","-0.00517"
"483.63000","-0.98998","-0.00510"
"484.63000","-0.98998","-0.00513"
"485.63000","-0.98998","-0.00514"
"486.63000","-0.98998","-0.00519"
"487.63000","-0.98998","-0.00520"
"488.63000","-0.98998","-0.00523"
"489.63000","-0.98998","-0.00509"
"490.63000","-0.98998","-0.00514"
"491.63000","-0.98998","-0.00518"
"492.63000","-0.98998","-0.00507"
"493.63000","-0.98998","-0.00513"
"494.63000","-0.98998","-0.00508"
"495.63000","-0.98998","-0.00500"
"496.63000","-0.98998","-0.00500"
"497.63000","-0.98998","-0.00515"
"498.63000","-0.98998","-0.00508"
"499.63000","-0.98998","-0.00510"
"500.63000","-0.98998","-0.00504"
"501.63000","-0.98998","-0.00496"
"502.63000","-0.98998","-0.00505"
"503.63000","-0.98998","-0.00504"
"504.63000","-0.98998","-0.00512"
"505.63000","-0.98998","-0.00504"
"506.63000","-0.98998","-0.00500"
"507.63000","-0.98998","-0.00507"
"508.63000","-0.98998","-0.00500"
"509.63000","-0.98998","-0.00495"
"510.63000","-0.98998","-0.00509"
"511.63000","-0.98998","-0.00495"
"512.63000","-0.98998","-0.00507"
"513.63000","-0.98998","-0.00502"
"514.63000","-0.98998","-0.00506"
"515.63000","-0.98998","-0.00499"
"516.63000","-0.98998","-0.00498"
"517.63000","-0.98998","-0.00490"
"518.63000","-0.98998","-0.00494"
"519.63000","-0.98998","-0.00490"
"520.63000","-0.98998","-0.00507"
"521.63000","-0.98998","-0.00500"
"522.63000","-0.98998","-0.00493"
"523.63000","-0.98998","-0.00493"
"524.63000","-0.98998","-0.00487"
"525.63000","-0.98998","-0.00504"
"526.63000","-0.98998","-0.00489"
"527.63000","-0.98998","-0.00490"
"528.63000","-0.98998","-0.00483"
"529.63000","-0.98998","-0.00483"
"530.63000","-0.98998","-0.00486"
"531.63000","-0.98998","-0.00499"
"532.63000","-0.98998","-0.00492"
"533.63000","-0.98998","-0.00486"
"534.63000","-0.98998","-0.00481"
"535.63000","-0.98998","-0.00494"
"536.63000","-0.98998","-0.00476"
"537.63000","-0.98998","-0.00490"
"538.63000","-0.98998","-0.00475"
"539.63000","-0.98998","-0.00487"
"540.63000","-0.98998","-0.00477"
"541.63000","-0.98998","-0.00483"
"542.63000","-0.98998","-0.00484"
"543.63000","-0.98998","-0.00481"
"544.63000","-0.98998","-0.00478"
"545.63000","-0.98998","-0.00477"
"546.63000","-0.98998","-0.00483"
"547.63000","-0.98998","-0.00484"
"548.63000","-0.98998","-0.00477"
"549.63000","-0.98998","-0.00482"
"550.63000","-0.98998","-0.00471"
"551.63000","-0.98998","-0.00474"
"552.63000","-0.98998","-0.00465"
"553.63000","-0.98998","-0.00485"
"554.63000","-0.98998","-0.00478"
"555.63000","-0.98998","-0.00476"
"556.63000","-0.98998","-0.00491"
"557.63000","-0.98998","-0.00466"
"558.63000","-0.98998","-0.00471"
"559.63000","-0.98998","-0.00468"
"560.63000","-0.98998","-0.00470"
"561.63000","-0.98998","-0.00465"
"562.63000","-0.98998","-0.00483"
"563.63000","-0.98998","-0.00472"
"564.63000","-0.98998","-0.00474"
"565.63000","-0.98998","-0.00459"
"566.63000","-0.98998","-0.00480"
"567.63000","-0.98998","-0.00466"
"568.63000","-0.98998","-0.00464"
"569.63000","-0.98998","-0.00471"
"570.63000","-0.98998","-0.00471"
"571.63000","-0.98998","-0.00471"
"572.63000","-0.98998","-0.00468"
"573.63000","-0.98998","-0.00466"
"574.63000","-0.98998","-0.00467"
"575.63000","-0.98998","-0.00460"
"576.63000","-0.98998","-0.00456"
"577.63000","-0.98998","-0.00463"
"578.63000","-0.98998","-0.00471"
"579.63000","-0.98998","-0.00457"
"580.63000","-0.98998","-0.00478"
"581.63000","-0.98998","-0.00479"
"582.63000","-0.98998","-0.00467"
"583.63000","-0.98998","-0.00461"
"584.63000","-0.98998","-0.00468"
"585.63000","-0.98998","-0.00458"
"586.63000","-0.98998","-0.00463"
"587.63000","-0.98998","-0.00464"
"588.63000","-0.98998","-0.00461"
"589.63000","-0.98998","-0.00462"
"590.63000","-0.98998","-0.00461"
"591.63000","-0.98998","-0.00459"
"592.63000","-0.98998","-0.00449"
"593.63000","-0.98998","-0.00455"
"594.63000","-0.98998","-0.00454"
"595.63000","-0.98998","-0.00455"
"596.63000","-0.98998","-0.00459"
"597.63000","-0.98998","-0.00459"
"598.63000","-0.98998","-0.00461"
"599.63000","-0.98998","-0.00451"
"600.63000","-0.98998","-0.00460"
"601.63000","-0.98998","-0.00450"
"602.63000","-0.98998","-0.00435"
"603.63000","-0.98998","-0.00452"
"604.63000","-0.98998","-0.00460"
"605.63000","-0.98998","-0.00460"
"606.63000","-0.98998","-0.00450"
"607.63000","-0.98998","-0.00455"
"608.63000","-0.98998","-0.00451"
"609.63000","-0.98998","-0.00443"
"610.63000","-0.98998","-0.00449"
"611.63000","-0.98998","-0.00449"
"612.63000","-0.98998","-0.00453"
"613.63000","-0.98998","-0.00445"
"614.63000","-0.98998","-0.00450"
"615.63000","-0.98998","-0.00458"
"616.63000","-0.98998","-0.00450"
"617.63000","-0.98998","-0.00446"
"618.63000","-0.98998","-0.00447"
"619.63000","-0.98998","-0.00440"
"620.63000","-0.98998","-0.00436"
"621.63000","-0.98998","-0.00454"
"622.63000","-0.98998","-0.00454"
"623.63000","-0.98998","-0.00445"
"624.63000","-0.98998","-0.00442"
"625.63000","-0.98998","-0.00431"
"626.63000","-0.98998","-0.00439"
"627.63000","-0.98998","-0.00441"
"628.63000","-0.98998","-0.00443"
"629.63000","-0.98998","-0.00447"
"630.63000","-0.98998","-0.00450"
"631.63000","-0.98998","-0.00437"
"632.63000","-0.98998","-0.00438"
"633.63000","-0.98998","-0.00444"
"634.63000","-0.98998","-0.00438"
"635.63000","-0.98998","-0.00433"
"636.63000","-0.98998","-0.00437"
"637.63000","-0.98998","-0.00440"
"638.63000","-0.98998","-0.00444"
"639.63000","-0.98998","-0.00439"
"640.63000","-0.98998","-0.00440"
"641.63000","-0.98998","-0.00431"
"642.63000","-0.98998","-0.00430"
"643.63000","-0.98998","-0.00433"
"644.63000","-0.98998","-0.00431"
"645.63000","-0.98998","-0.00438"
"646.63000","-0.98998","-0.00438"
"647.63000","-0.98998","-0.00438"
"648.63000","-0.98998","-0.00438"
"649.63000","-0.98998","-0.00438"
"650.63000","-0.98998","-0.00435"
"651.63000","-0.98998","-0.00435"
"652.63000","-0.98998","-0.00434"
"653.63000","-0.98998","-0.00444"
"654.63000","-0.98998","-0.00426"
"655.63000","-0.98998","-0.00440"
"656.63000","-0.98998","-0.00425"
"657.63000","-0.98998","-0.00444"
"658.63000","-0.98998","-0.00420"
"659.63000","-0.98998","-0.00433"
"660.63000","-0.98998","-0.00423"
"661.63000","-0.98998","-0.00427"
"662.63000","-0.98998","-0.00421"
"663.63000","-0.98998","-0.00438"
"664.63000","-0.98998","-0.00436"
"665.63000","-0.98998","-0.00427"
"666.63000","-0.98998","-0.00421"
"667.63000","-0.98998","-0.00429"
"668.63000","-0.98998","-0.00422"
"669.63000","-0.98998","-0.00429"
"670.63000","-0.98998","-0.00427"
"671.63000","-0.98998","-0.00426"
"672.63000","-0.98998","-0.00424"
"673.63000","-0.98998","-0.00422"
"674.63000","-0.98998","-0.00432"
"675.63000","-0.98998","-0.00426"
"676.63000","-0.98998","-0.00415"
"677.63000","-0.98998","-0.00419"
"678.63000","-0.98998","-0.00422"
"679.63000","-0.98998","-0.00418"
"680.63000","-0.98998","-0.00429"
"681.63000","-0.98998","-0.00421"
"682.63000","-0.98998","-0.00434"
"683.63000","-0.98998","-0.00416"
"684.63000","-0.98998","-0.00421"
"685.63000","-0.98998","-0.00416"
"686.63000","-0.98998","-0.00429"
"687.63000","-0.98998","-0.00416"
"688.63000","-0.98998","-0.00420"
"689.63000","-0.98998","-0.00415"
"690.53100","-1.00550","-0.00583"
"691.53100","-1.03866","-0.00899"
"692.53100","-1.07162","-0.01310"
"693.53100","-1.10458","-0.01722"
"694.53100","-1.13768","-0.02143"
"695.53100","-1.17072","-0.02549"
"696.53100","-1.20370","-0.02884"
"697.53100","-1.23656","-0.03191"
"698.53100","-1.26944","-0.03495"
"699.53100","-1.30260","-0.03845"
"700.53100","-1.33558","-0.04201"
"701.53100","-1.36866","-0.04561"
"702.53100","-1.40166","-0.04933"
"703.53100","-1.43476","-0.05306"
"704.53100","-1.46762","-0.05752"
"705.36200","-1.48562","-0.05584"
"706.36200","-1.48520","-0.04798"
"707.36200","-1.48518","-0.04418"
"708.36200","-1.48516","-0.04127"
"709.36200","-1.48518","-0.03913"
"710.36200","-1.48518","-0.03726"
"711.36200","-1.48518","-0.03578"
"712.36200","-1.48518","-0.03441"
"713.36200","-1.48518","-0.03332"
"714.36200","-1.48518","-0.03221"
"715.36200","-1.48518","-0.03157"
"716.36200","-1.48518","-0.03056"
"717.36200","-1.48518","-0.02979"
"718.36200","-1.48518","-0.02906"
"719.36200","-1.48518","-0.02858"
"720.36200","-1.48518","-0.02791"
"721.36200","-1.48518","-0.02733"
"722.36200","-1.48518","-0.02702"
"723.36200","-1.48518","-0.02646"
"724.36200","-1.48518","-0.02598"
"725.36200","-1.48518","-0.02570"
"726.36200","-1.48518","-0.02520"
"727.36200","-1.48518","-0.02473"
"728.36200","-1.48518","-0.02434"
"729.36200","-1.48518","-0.02409"
"730.36200","-1.48518","-0.02365"
"731.36200","-1.48518","-0.02347"
"732.36200","-1.48518","-0.02328"
"733.36200","-1.48518","-0.02295"
"734.36200","-1.48518","-0.02257"
"735.36200","-1.48518","-0.02242"
"736.36200","-1.48518","-0.02203"
"737.36200","-1.48518","-0.02178"
"738.36200","-1.48518","-0.02166"
"739.36200","-1.48518","-0.02148"
"740.36200","-1.48518","-0.02134"
"741.36200","-1.48518","-0.02116"
"742.36200","-1.48518","-0.02091"
"743.36200","-1.48518","-0.02064"
"744.36200","-1.48518","-0.02048"
"745.36200","-1.48518","-0.02026"
"746.36200","-1.48518","-0.02014"
"747.36200","-1.48518","-0.01998"
"748.36200","-1.48518","-0.01981"
"749.36200","-1.48518","-0.01960"
"750.36200","-1.48518","-0.01945"
"751.36200","-1.48518","-0.01927"
"752.36200","-1.48518","-0.01920"
"753.36200","-1.48518","-0.01901"
"754.36200","-1.48518","-0.01892"
"755.36200","-1.48518","-0.01872"
"756.36200","-1.48518","-0.01862"
"757.36200","-1.48518","-0.01851"
"758.36200","-1.48518","-0.01840"
"759.36200","-1.48518","-0.01825"
"760.36200","-1.48518","-0.01807"
"761.36200","-1.48518","-0.01800"
"762.36200","-1.48518","-0.01792"
"763.36200","-1.48518","-0.01782"
"764.36200","-1.48518","-0.01780"
"765.36200","-1.48518","-0.01770"
"766.36200","-1.48518","-0.01743"
"767.36200","-1.48518","-0.01737"
"768.36200","-1.48518","-0.01728"
"769.36200","-1.48518","-0.01726"
"770.36200","-1.48518","-0.01714"
"771.36200","-1.48518","-0.01696"
"772.36200","-1.48518","-0.01686"
"773.36200","-1.48518","-0.01690"
"774.36200","-1.48518","-0.01668"
"775.36200","-1.48518","-0.01663"
"776.36200","-1.48518","-0.01660"
"777.36200","-1.48518","-0.01650"
"778.36200","-1.48518","-0.01640"
"779.36200","-1.48518","-0.01633"
"780.36200","-1.48518","-0.01625"
"781.36200","-1.48518","-0.01620"
"782.36200","-1.48518","-0.01612"
"783.36200","-1.48518","-0.01598"
"784.36200","-1.48518","-0.01597"
"785.36200","-1.48518","-0.01581"
"786.36200","-1.48518","-0.01561"
"787.36200","-1.48518","-0.01577"
"788.36200","-1.48518","-0.01562"
"789.36200","-1.48518","-0.01562"
"790.36200","-1.48518","-0.01557"
"791.36200","-1.48518","-0.01543"
"792.36200","-1.48518","-0.01530"
"793.36200","-1.48518","-0.01526"
"794.36200","-1.48518","-0.01511"
"795.36200","-1.48518","-0.01526"
"796.36200","-1.48518","-0.01523"
"797.36200","-1.48518","-0.01515"
"798.36200","-1.48518","-0.01497"
"799.36200","-1.48518","-0.01498"
"800.36200","-1.48518","-0.01496"
"801.36200","-1.48518","-0.01487"
"802.36200","-1.48518","-0.01474"
"803.36200","-1.48518","-0.01469"
"804.36200","-1.48518","-0.01469"
"805.36200","-1.48518","-0.01464"
"806.36200","-1.48518","-0.01469"
"807.36200","-1.48518","-0.01458"
"808.36200","-1.48518","-0.01451"
"809.36200","-1.48518","-0.01429"
"810.36200","-1.48518","-0.01430"
"811.36200","-1.48518","-0.01436"
"812.36200","-1.48518","-0.01430"
"813.36200","-1.48518","-0.01426"
"814.36200","-1.48518","-0.01427"
"815.36200","-1.48518","-0.01408"
"816.36200","-1.48518","-0.01409"
"817.36200","-1.48518","-0.01393"
"818.36200","-1.48518","-0.01397"
"819.36200","-1.48518","-0.01391"
"820.36200","-1.48518","-0.01391"
"821.36200","-1.48518","-0.01378"
"822.36200","-1.48518","-0.01381"
"823.36200","-1.48518","-0.01380"
"824.36200","-1.48518","-0.01370"
"825.36200","-1.48518","-0.01358"
"826.36200","-1.48518","-0.01360"
"827.36200","-1.48518","-0.01359"
"828.36200","-1.48518","-0.01350"
"829.36200","-1.48518","-0.01354"
"830.36200","-1.48518","-0.01362"
"831.36200","-1.48518","-0.01339"
"832.36200","-1.48518","-0.01339"
"833.36200","-1.48518","-0.01332"
"834.36200","-1.48518","-0.01334"
"835.36200","-1.48518","-0.01320"
"836.36200","-1.48518","-0.01326"
"837.36200","-1.48518","-0.01331"
"838.36200","-1.48518","-0.01328"
"839.36200","-1.48518","-0.01314"
"840.36200","-1.48518","-0.01300"
"841.36200","-1.48518","-0.01301"
"842.36200","-1.48518","-0.01296"
"843.36200","-1.48518","-0.01300"
"844.36200","-1.48518","-0.01286"
"845.36200","-1.48518","-0.01298"
"846.36200","-1.48518","-0.01297"
"847.36200","-1.48518","-0.01291"
"848.36200","-1.48518","-0.01280"
"849.36200","-1.48518","-0.01285"
"850.36200","-1.48518","-0.01271"
"851.36200","-1.48518","-0.01262"
"852.36200","-1.48518","-0.01265"
"853.36200","-1.48518","-0.01278"
"854.36200","-1.48518","-0.01255"
"855.36200","-1.48518","-0.01266"
"856.36200","-1.48518","-0.01262"
"857.36200","-1.48518","-0.01264"
"858.36200","-1.48518","-0.01244"
"859.36200","-1.48518","-0.01246"
"860.36200","-1.48518","-0.01238"
"861.36200","-1.48518","-0.01248"
"862.36200","-1.48518","-0.01236"
"863.36200","-1.48518","-0.01242"
"864.36200","-1.48518","-0.01235"
"865.36200","-1.48518","-0.01244"
"866.36200","-1.48518","-0.01231"
"867.36200","-1.48518","-0.01229"
"868.36200","-1.48518","-0.01222"
"869.36200","-1.48518","-0.01220"
"870.36200","-1.48518","-0.01203"
"871.36200","-1.48518","-0.01209"
"872.36200","-1.48518","-0.01212"
"873.36200","-1.48518","-0.01212"
"874.36200","-1.48518","-0.01205"
"875.36200","-1.48518","-0.01202"
"876.36200","-1.48518","-0.01200"
"877.36200","-1.48518","-0.01197"
"878.36200","-1.48518","-0.01191"
"879.36200","-1.48518","-0.01186"
"880.36200","-1.48518","-0.01181"
"881.36200","-1.48518","-0.01178"
"882.36200","-1.48518","-0.01194"
"883.36200","-1.48518","-0.01192"
"884.36200","-1.48518","-0.01194"
"885.36200","-1.48518","-0.01175"
"886.36200","-1.48518","-0.01186"
"887.36200","-1.48518","-0.01168"
"888.36200","-1.48518","-0.01177"
"889.36200","-1.48518","-0.01165"
"890.36200","-1.48518","-0.01169"
"891.36200","-1.48518","-0.01159"
"892.36200","-1.48518","-0.01158"
"893.36200","-1.48518","-0.01167"
"894.36200","-1.48518","-0.01171"
"895.36200","-1.48518","-0.01157"
"896.36200","-1.48518","-0.01161"
"897.36200","-1.48518","-0.01160"
"898.36200","-1.48518","-0.01153"
"899.36200","-1.48518","-0.01142"
"900.36200","-1.48518","-0.01143"
"901.36200","-1.48518","-0.01151"
"902.36200","-1.48518","-0.01149"
"903.36200","-1.48518","-0.01135"
"904.36200","-1.48518","-0.01133"
"905.36200","-1.48518","-0.01133"
"906.36200","-1.48518","-0.01136"
"907.36200","-1.48518","-0.01130"
"908.36200","-1.48518","-0.01139"
"909.36200","-1.48518","-0.01119"
"910.36200","-1.48518","-0.01121"
"911.36200","-1.48518","-0.01119"
"912.36200","-1.48518","-0.01127"
"913.36200","-1.48518","-0.01117"
"914.36200","-1.48518","-0.01126"
"915.36200","-1.48520","-0.01118"
"916.36200","-1.48520","-0.01120"
"917.36200","-1.48520","-0.01108"
"918.36200","-1.48520","-0.01109"
"919.36200","-1.48520","-0.01097"
"920.36200","-1.48520","-0.01109"
"921.36200","-1.48520","-0.01097"
"922.36200","-1.48520","-0.01102"
"923.36200","-1.48520","-0.01107"
"924.36200","-1.48520","-0.01104"
"925.36200","-1.48520","-0.01094"
"926.36200","-1.48520","-0.01098"
"927.36200","-1.48520","-0.01101"
"928.36200","-1.48520","-0.01081"
"929.36200","-1.48520","-0.01085"
"930.36200","-1.48520","-0.01078"
"931.36200","-1.48520","-0.01092"
"932.36200","-1.48520","-0.01078"
"933.36200","-1.48520","-0.01081"
"934.36200","-1.48520","-0.01089"
"935.36200","-1.48520","-0.01091"
"936.36200","-1.48520","-0.01071"
"937.36200","-1.48520","-0.01081"
"938.36200","-1.48520","-0.01062"
"939.36200","-1.48520","-0.01082"
"940.36200","-1.48520","-0.01074"
"941.36200","-1.48520","-0.01073"
"942.36200","-1.48520","-0.01077"
"943.36200","-1.48520","-0.01076"
"944.36200","-1.48520","-0.01072"
"945.36200","-1.48520","-0.01067"
"946.36200","-1.48520","-0.01055"
"947.36200","-1.48520","-0.01066"
"948.36200","-1.48520","-0.01046"
"949.36200","-1.48520","-0.01063"
"950.36200","-1.48520","-0.01051"
"951.36200","-1.48520","-0.01061"
"952.36200","-1.48520","-0.01054"
"953.36200","-1.48520","-0.01059"
"954.36200","-1.48520","-0.01043"
"955.36200","-1.48520","-0.01044"
"956.36200","-1.48520","-0.01037"
"957.36200","-1.48520","-0.01050"
"958.36200","-1.48520","-0.01041"
"959.36200","-1.48520","-0.01047"
"960.36200","-1.48520","-0.01045"
"961.36200","-1.48520","-0.01038"
"962.36200","-1.48520","-0.01049"
"963.36200","-1.48520","-0.01034"
"964.36200","-1.48520","-0.01037"
"965.36200","-1.48520","-0.01024"
"966.36200","-1.48520","-0.01032"
"967.36200","-1.48520","-0.01017"
"968.36200","-1.48520","-0.01029"
"969.36200","-1.48520","-0.01028"
"970.36200","-1.48520","-0.01035"
"971.36200","-1.48520","-0.01026"
"972.36200","-1.48520","-0.01027"
"973.36200","-1.48520","-0.01013"
"974.36200","-1.48520","-0.01024"
"975.36200","-1.48520","-0.01011"
"976.36200","-1.48520","-0.01022"
"977.36200","-1.48520","-0.01006"
"978.36200","-1.48520","-0.01005"
"979.36200","-1.48520","-0.01007"
"980.36200","-1.48520","-0.01024"
"981.36200","-1.48520","-0.01004"
"982.36200","-1.48520","-0.01011"
"983.36200","-1.48520","-0.01002"
"984.36200","-1.48520","-0.00998"
"985.36200","-1.48520","-0.01001"
"986.36200","-1.48520","-0.01003"
"987.36200","-1.48520","-0.01010"
"988.36200","-1.48520","-0.01004"
"989.36200","-1.48520","-0.01003"
"990.36200","-1.48520","-0.00996"
"991.36200","-1.48520","-0.00979"
"992.36200","-1.48520","-0.00995"
"993.36200","-1.48520","-0.01001"
"994.36200","-1.48520","-0.00990"
"995.36200","-1.48520","-0.00998"
"996.36200","-1.48520","-0.00966"
"997.36200","-1.48520","-0.00985"
"998.36200","-1.48520","-0.00986"
"999.36200","-1.48520","-0.00984"
"1,000.36200","-1.48520","-0.00973"
"1,001.36200","-1.48520","-0.00985"
"1,002.36200","-1.48520","-0.00980"
"1,003.36200","-1.48520","-0.00993"
"1,004.36200","-1.48520","-0.00977"
"1,005.36200","-1.48520","-0.00990"
"1,006.36200","-1.48520","-0.00984"
"1,007.36200","-1.48520","-0.00981"
"1,008.36200","-1.48520","-0.00970"
"1,009.36200","-1.48520","-0.00969"
"1,010.36200","-1.48520","-0.00973"
"1,011.36200","-1.48520","-0.00986"
"1,012.36200","-1.48520","-0.00972"
"1,013.36200","-1.48520","-0.00980"
"1,014.36200","-1.48520","-0.00965"
"1,015.36200","-1.48520","-0.00968"
"1,016.36200","-1.48520","-0.00956"
"1,017.36200","-1.48520","-0.00966"
"1,018.36200","-1.48520","-0.00966"
"1,019.36200","-1.48520","-0.00962"
"1,020.36200","-1.48520","-0.00966"
"1,021.36200","-1.48520","-0.00971"
"1,022.36200","-1.48520","-0.00962"
"1,023.36200","-1.48520","-0.00967"
"1,024.36200","-1.48520","-0.00962"
"1,025.36200","-1.48520","-0.00946"
"1,026.36200","-1.48520","-0.00950"
"1,027.36200","-1.48520","-0.00946"
"1,028.36200","-1.48520","-0.00952"
"1,029.36200","-1.48520","-0.00956"
"1,030.36200","-1.48520","-0.00961"
"1,031.36200","-1.48520","-0.00954"
"1,032.36200","-1.48520","-0.00945"
"1,033.36200","-1.48520","-0.00946"
"1,034.36200","-1.48520","-0.00945"
"1,035.36200","-1.48520","-0.00941"
"1,036.36200","-1.48520","-0.00955"
"1,037.36200","-1.48520","-0.00947"
"1,038.36200","-1.48520","-0.00940"
"1,039.36200","-1.48520","-0.00947"
"1,040.36200","-1.48520","-0.00944"
"1,041.36200","-1.48520","-0.00939"
"1,042.36200","-1.48520","-0.00927"
"1,043.36200","-1.48520","-0.00931"
"1,044.36200","-1.48520","-0.00929"
"1,045.36200","-1.48520","-0.00936"
"1,046.36200","-1.48520","-0.00940"
"1,047.36200","-1.48520","-0.00935"
"1,048.36200","-1.48520","-0.00935"
"1,049.36200","-1.48520","-0.00925"
"1,050.36200","-1.48520","-0.00917"
"1,051.36200","-1.48520","-0.00928"
"1,052.36200","-1.48520","-0.00926"
"1,053.36200","-1.48520","-0.00928"
"1,054.36200","-1.48520","-0.00925"
"1,055.36200","-1.48520","-0.00937"
"1,056.36200","-1.48520","-0.00929"
"1,057.36200","-1.48520","-0.00920"
"1,058.36200","-1.48520","-0.00920"
"1,059.36200","-1.48520","-0.00921"
"1,060.36200","-1.48520","-0.00910"
"1,061.36200","-1.48520","-0.00915"
"1,062.36200","-1.48520","-0.00923"
"1,063.36200","-1.48520","-0.00919"
"1,064.36200","-1.48520","-0.00921"
"1,065.36200","-1.48520","-0.00923"
"1,066.36200","-1.48520","-0.00919"
"1,067.36200","-1.48520","-0.00910"
"1,068.36200","-1.48520","-0.00905"
"1,069.36200","-1.48520","-0.00899"
"1,070.36200","-1.48520","-0.00908"
"1,071.36200","-1.48520","-0.00912"
"1,072.36200","-1.48520","-0.00905"
"1,073.36200","-1.48520","-0.00904"
"1,074.36200","-1.48520","-0.00906"
"1,075.36200","-1.48520","-0.00898"
"1,076.36200","-1.48520","-0.00906"
"1,077.36200","-1.48520","-0.00905"
"1,078.36200","-1.48520","-0.00893"
"1,079.36200","-1.48520","-0.00893"
"1,080.36200","-1.48520","-0.00909"
"1,081.36200","-1.48520","-0.00903"
"1,082.36200","-1.48520","-0.00903"
"1,083.36200","-1.48520","-0.00897"
"1,084.36200","-1.48520","-0.00902"
"1,085.36200","-1.48520","-0.00896"
"1,086.36200","-1.48520","-0.00897"
"1,087.36200","-1.48520","-0.00897"
"1,088.36200","-1.48520","-0.00893"
"1,089.36200","-1.48520","-0.00895"
"1,090.36200","-1.48520","-0.00889"
"1,091.36200","-1.48520","-0.00901"
"1,092.36200","-1.48520","-0.00892"
"1,093.36200","-1.48520","-0.00889"
"1,094.36200","-1.48520","-0.00885"
"1,095.36200","-1.48520","-0.00888"
"1,096.36200","-1.48520","-0.00876"
"1,097.36200","-1.48520","-0.00891"
"1,098.36200","-1.48520","-0.00883"
"1,099.36200","-1.48520","-0.00895"
"1,100.36200","-1.48520","-0.00885"
"1,101.36200","-1.48520","-0.00881"
"1,102.36200","-1.48520","-0.00883"
"1,103.36200","-1.48520","-0.00876"
"1,104.36200","-1.48520","-0.00874"
"1,105.36200","-1.48520","-0.00875"
"1,106.36200","-1.48520","-0.00875"
"1,107.36200","-1.48520","-0.00876"
"1,108.36200","-1.48520","-0.00871"
"1,109.36200","-1.48520","-0.00877"
"1,110.36200","-1.48520","-0.00882"
"1,111.36200","-1.48520","-0.00873"
"1,112.36200","-1.48520","-0.00873"
"1,113.36200","-1.48520","-0.00861"
"1,114.36200","-1.48520","-0.00873"
"1,115.36200","-1.48520","-0.00869"
"1,116.36200","-1.48520","-0.00881"
"1,117.36200","-1.48520","-0.00880"
"1,118.36200","-1.48520","-0.00868"
"1,119.36200","-1.48520","-0.00873"
"1,120.36200","-1.48520","-0.00875"
"1,121.36200","-1.48520","-0.00869"
"1,122.36200","-1.48520","-0.00863"
"1,123.36200","-1.48520","-0.00857"
"1,124.36200","-1.48520","-0.00861"
"1,125.36200","-1.48520","-0.00872"
"1,126.36200","-1.48520","-0.00869"
"1,127.36200","-1.48520","-0.00866"
"1,128.36200","-1.48520","-0.00870"
"1,129.36200","-1.48520","-0.00865"
"1,130.36200","-1.48520","-0.00861"
"1,131.36200","-1.48520","-0.00858"
"1,132.36200","-1.48520","-0.00869"
"1,133.36200","-1.48520","-0.00865"
"1,134.36200","-1.48520","-0.00857"
"1,135.36200","-1.48520","-0.00859"
"1,136.36200","-1.48520","-0.00863"
"1,137.36200","-1.48520","-0.00852"
"1,138.36200","-1.48520","-0.00855"
"1,139.36200","-1.48520","-0.00852"
"1,140.36200","-1.48520","-0.00860"
"1,141.36200","-1.48520","-0.00853"
"1,142.36200","-1.48520","-0.00853"
"1,143.36200","-1.48520","-0.00857"
"1,144.36200","-1.48520","-0.00853"
"1,145.36200","-1.48520","-0.00858"
"1,146.36200","-1.48520","-0.00848"
"1,147.36200","-1.48520","-0.00849"
"1,148.36200","-1.48520","-0.00851"
"1,149.36200","-1.48520","-0.00844"
"1,150.36200","-1.48520","-0.00853"
"1,151.36200","-1.48520","-0.00849"
"1,152.36200","-1.48520","-0.00862"
"1,153.36200","-1.48520","-0.00842"
"1,154.36200","-1.48520","-0.00839"
"1,155.36200","-1.48520","-0.00837"
"1,156.36200","-1.48520","-0.00850"
"1,157.36200","-1.48520","-0.00837"
"1,158.36200","-1.48520","-0.00844"
"1,159.36200","-1.48520","-0.00841"
"1,160.36200","-1.48520","-0.00853"
"1,161.36200","-1.48520","-0.00840"
"1,162.36200","-1.48520","-0.00853"
"1,163.36200","-1.48520","-0.00843"
"1,164.36200","-1.48520","-0.00839"
"1,165.36200","-1.48520","-0.00830"
"1,166.36200","-1.48520","-0.00838"
"1,167.36200","-1.48520","-0.00830"
"1,168.36200","-1.48520","-0.00844"
"1,169.36200","-1.48520","-0.00845"
"1,170.36200","-1.48520","-0.00844"
"1,171.36200","-1.48520","-0.00837"
"1,172.36200","-1.48520","-0.00826"
"1,173.36200","-1.48520","-0.00827"
"1,174.36200","-1.48520","-0.00828"
"1,175.36200","-1.48520","-0.00832"
"1,176.36200","-1.48520","-0.00826"
"1,177.36200","-1.48520","-0.00832"
"1,178.36200","-1.48520","-0.00824"
"1,179.36200","-1.48520","-0.00833"
"1,180.36200","-1.48520","-0.00833"
"1,181.36200","-1.48520","-0.00835"
"1,182.36200","-1.48520","-0.00823"
"1,183.36200","-1.48520","-0.00825"
"1,184.36200","-1.48520","-0.00821"
"1,185.36200","-1.48520","-0.00840"
"1,186.36200","-1.48520","-0.00822"
"1,187.36200","-1.48520","-0.00829"
"1,188.36200","-1.48520","-0.00830"
"1,189.36200","-1.48520","-0.00836"
"1,190.36200","-1.48520","-0.00822"
"1,191.36200","-1.48520","-0.00823"
"1,192.36200","-1.48520","-0.00812"
"1,193.36200","-1.48520","-0.00820"
"1,194.36200","-1.48520","-0.00815"
"1,195.36200","-1.48520","-0.00816"
"1,196.36200","-1.48520","-0.00822"
"1,197.36200","-1.48520","-0.00826"
"1,198.36200","-1.48520","-0.00827"
"1,199.36200","-1.48520","-0.00823"
"1,200.36200","-1.48520","-0.00822"
"1,201.36200","-1.48520","-0.00809"
"1,202.36200","-1.48520","-0.00830"
"1,203.36200","-1.48520","-0.00809"
"1,204.36200","-1.48520","-0.00815"
"1,205.36200","-1.48520","-0.00821"
"1,206.36200","-1.48520","-0.00818"
"1,207.36200","-1.48520","-0.00813"
"1,208.36200","-1.48520","-0.00817"
"1,209.36200","-1.48520","-0.00803"
"1,210.36200","-1.48520","-0.00808"
"1,211.36200","-1.48520","-0.00798"
"1,212.36200","-1.48520","-0.00810"
"1,213.36200","-1.48520","-0.00815"
"1,214.36200","-1.48520","-0.00807"
"1,215.36200","-1.48520","-0.00810"
"1,216.36200","-1.48520","-0.00804"
"1,217.36200","-1.48520","-0.00794"
"1,218.36200","-1.48520","-0.00795"
"1,219.36200","-1.48520","-0.00808"
"1,220.36200","-1.48520","-0.00797"
"1,221.36200","-1.48520","-0.00805"
"1,222.36200","-1.48520","-0.00801"
"1,223.36200","-1.48520","-0.00799"
"1,224.36200","-1.48520","-0.00809"
"1,225.36200","-1.48520","-0.00804"
"1,226.36200","-1.48520","-0.00802"
"1,227.36200","-1.48520","-0.00789"
"1,228.36200","-1.48520","-0.00791"
"1,229.36200","-1.48520","-0.00803"
"1,230.36200","-1.48520","-0.00793"
"1,231.36200","-1.48520","-0.00800"
"1,232.36200","-1.48520","-0.00806"
"1,233.36200","-1.48520","-0.00788"
"1,234.36200","-1.48520","-0.00775"
"1,235.36200","-1.48520","-0.00796"
"1,236.36200","-1.48520","-0.00792"
"1,237.36200","-1.48520","-0.00803"
"1,238.36200","-1.48520","-0.00802"
"1,239.36200","-1.48520","-0.00795"
"1,240.36200","-1.48520","-0.00794"
"1,241.36200","-1.48520","-0.00788"
"1,242.36200","-1.48520","-0.00795"
"1,243.36200","-1.48520","-0.00784"
"1,244.36200","-1.48520","-0.00792"
"1,245.36200","-1.48520","-0.00784"
"1,246.36200","-1.48520","-0.00798"
"1,247.36200","-1.48520","-0.00783"
"1,248.36200","-1.48520","-0.00793"
"1,249.36200","-1.48520","-0.00800"
"1,250.36200","-1.48520","-0.00777"
"1,251.36200","-1.48520","-0.00769"
"1,252.36200","-1.48520","-0.00783"
"1,253.36200","-1.48520","-0.00785"
"1,254.36200","-1.48520","-0.00791"
"1,255.36200","-1.48520","-0.00791"
"1,256.36200","-1.48520","-0.00794"
"1,257.36200","-1.48520","-0.00787"
"1,258.36200","-1.48520","-0.00782"
"1,259.36200","-1.48520","-0.00788"
"1,260.36200","-1.48520","-0.00774"
"1,261.36200","-1.48520","-0.00783"
"1,262.36200","-1.48520","-0.00779"
"1,263.36200","-1.48520","-0.00785"
"1,264.36200","-1.48520","-0.00784"
"1,265.36200","-1.48520","-0.00780"
"1,266.36200","-1.48520","-0.00780"
"1,267.36200","-1.48520","-0.00782"
"1,268.36200","-1.48520","-0.00770"
"1,269.36200","-1.48520","-0.00774"
"1,270.36200","-1.48520","-0.00778"
"1,271.36200","-1.48520","-0.00778"
"1,272.36200","-1.48520","-0.00786"
"1,273.36200","-1.48520","-0.00786"
"1,274.36200","-1.48520","-0.00777"
"1,275.36200","-1.48520","-0.00780"
"1,276.36200","-1.48520","-0.00769"
"1,277.36200","-1.48520","-0.00767"
"1,278.36200","-1.48520","-0.00775"
"1,279.36200","-1.48520","-0.00777"
"1,280.36200","-1.48520","-0.00776"
"1,281.36200","-1.48520","-0.00773"
"1,282.36200","-1.48520","-0.00766"
"1,283.36200","-1.48520","-0.00776"
"1,284.36200","-1.48520","-0.00767"
"1,285.36200","-1.48520","-0.00770"
"1,286.36200","-1.48520","-0.00761"
"1,287.36200","-1.48520","-0.00759"
"1,288.36200","-1.48520","-0.00771"
"1,289.36200","-1.48520","-0.00772"
"1,290.36200","-1.48520","-0.00778"
"1,291.36200","-1.48520","-0.00768"
"1,292.36200","-1.48520","-0.00762"
"1,293.36200","-1.48520","-0.00767"
"1,294.36200","-1.48520","-0.00763"
"1,295.36200","-1.48520","-0.00759"
"1,296.36200","-1.48520","-0.00777"
"1,297.36200","-1.48520","-0.00765"
"1,298.36200","-1.48520","-0.00766"
"1,299.36200","-1.48520","-0.00759"
"1,300.36200","-1.48520","-0.00759"
"1,301.36200","-1.48520","-0.00772"
"1,302.36200","-1.48520","-0.00759"
"1,303.36200","-1.48520","-0.00758"
"1,304.36200","-1.48520","-0.00768"
"1,305.36200","-1.48520","-0.00758"
"1,306.36200","-1.48520","-0.00762"
"1,307.36200","-1.48520","-0.00765"
"1,308.36200","-1.48520","-0.00772"
"1,309.36200","-1.48520","-0.00761"
"1,310.36200","-1.48520","-0.00757"
"1,311.36200","-1.48520","-0.00753"
"1,312.36200","-1.48520","-0.00757"
"1,313.36200","-1.48520","-0.00759"
"1,314.36200","-1.48520","-0.00760"
"1,315.36200","-1.48520","-0.00758"
"1,316.36200","-1.48520","-0.00754"
"1,317.36200","-1.48520","-0.00754"
"1,318.36200","-1.48520","-0.00758"
"1,319.36200","-1.48520","-0.00758"
"1,320.36200","-1.48520","-0.00759"
"1,321.36200","-1.48520","-0.00756"
"1,322.36200","-1.48520","-0.00747"
"1,323.36200","-1.48520","-0.00753"
"1,324.36200","-1.48520","-0.00756"
"1,325.36200","-1.48520","-0.00753"
"1,326.36200","-1.48520","-0.00755"
"1,327.36200","-1.48520","-0.00746"
"1,328.36200","-1.48520","-0.00737"
"1,329.36200","-1.48520","-0.00745"
"1,330.36200","-1.48520","-0.00750"
"1,331.36200","-1.48520","-0.00761"
"1,332.36200","-1.48520","-0.00745"
"1,333.36200","-1.48520","-0.00756"
"1,334.36200","-1.48520","-0.00754"
"1,335.36200","-1.48520","-0.00742"
"1,336.36200","-1.48520","-0.00737"
"1,337.36200","-1.48520","-0.00752"
"1,338.36200","-1.48520","-0.00747"
"1,339.36200","-1.48520","-0.00743"
"1,340.36200","-1.48520","-0.00740"
"1,341.36200","-1.48520","-0.00758"
"1,342.36200","-1.48520","-0.00750"
"1,343.36200","-1.48520","-0.00740"
"1,344.36200","-1.48520","-0.00741"
"1,345.36200","-1.48520","-0.00739"
"1,346.36200","-1.48520","-0.00738"
"1,347.36200","-1.48520","-0.00741"
"1,348.36200","-1.48520","-0.00746"
"1,349.36200","-1.48520","-0.00745"
"1,350.36200","-1.48520","-0.00740"
"1,351.36200","-1.48520","-0.00746"
"1,352.36200","-1.48520","-0.00739"
"1,353.36200","-1.48520","-0.00740"
"1,354.36200","-1.48520","-0.00740"
"1,355.36200","-1.48520","-0.00740"
"1,356.36200","-1.48520","-0.00736"
"1,357.36200","-1.48520","-0.00749"
"1,358.36200","-1.48520","-0.00745"
"1,359.36200","-1.48520","-0.00741"
"1,360.36200","-1.48520","-0.00741"
"1,361.36200","-1.48520","-0.00739"
"1,362.36200","-1.48520","-0.00734"
"1,363.36200","-1.48520","-0.00732"
"1,364.36200","-1.48520","-0.00737"
"1,365.36200","-1.48520","-0.00736"
"1,366.36200","-1.48520","-0.00740"
"1,367.36200","-1.48520","-0.00739"
"1,368.36200","-1.48520","-0.00733"
"1,369.36200","-1.48520","-0.00741"
"1,370.36200","-1.48520","-0.00734"
"1,371.36200","-1.48520","-0.00738"
"1,372.36200","-1.48520","-0.00735"
"1,373.36200","-1.48520","-0.00736"
"1,374.36200","-1.48520","-0.00746"
"1,375.36200","-1.48520","-0.00742"
"1,376.36200","-1.48520","-0.00730"
"1,377.36200","-1.48520","-0.00733"
"1,378.36200","-1.48520","-0.00720"
"1,379.36200","-1.48520","-0.00722"
"1,380.36200","-1.48520","-0.00723"
"1,381.36200","-1.48520","-0.00732"
"1,382.36200","-1.48520","-0.00718"
"1,383.36200","-1.48520","-0.00726"
"1,384.36200","-1.48520","-0.00733"
"1,385.36200","-1.48520","-0.00733"
"1,386.36200","-1.48520","-0.00729"
"1,387.36200","-1.48520","-0.00729"
"1,388.36200","-1.48520","-0.00722"
"1,389.36200","-1.48520","-0.00729"
"1,390.36200","-1.48520","-0.00728"
"1,391.36200","-1.48520","-0.00728"
"1,392.36200","-1.48520","-0.00727"
"1,393.36200","-1.48520","-0.00734"
"1,394.36200","-1.48520","-0.00718"
"1,395.36200","-1.48520","-0.00726"
"1,396.36200","-1.48520","-0.00721"
"1,397.36200","-1.48520","-0.00724"
"1,398.36200","-1.48520","-0.00721"
"1,399.36200","-1.48520","-0.00717"
"1,400.36200","-1.48520","-0.00729"
"1,401.36200","-1.48520","-0.00722"
"1,402.36200","-1.48520","-0.00730"
"1,403.36200","-1.48520","-0.00715"
"1,404.36200","-1.48520","-0.00724"
"1,405.36200","-1.48520","-0.00716"
"1,406.36200","-1.48520","-0.00724"
"1,407.36200","-1.48520","-0.00707"
"1,408.36200","-1.48520","-0.00722"
"1,409.36200","-1.48520","-0.00718"
"1,410.36200","-1.48520","-0.00718"
"1,411.36200","-1.48520","-0.00719"
"1,412.36200","-1.48520","-0.00726"
"1,413.36200","-1.48520","-0.00713"
"1,414.36200","-1.48520","-0.00709"
"1,415.36200","-1.48520","-0.00716"
"1,416.36200","-1.48520","-0.00720"
"1,417.36200","-1.48520","-0.00707"
"1,418.36200","-1.48520","-0.00722"
"1,419.36200","-1.48520","-0.00721"
"1,420.36200","-1.48520","-0.00711"
"1,421.36200","-1.48520","-0.00718"
"1,422.36200","-1.48520","-0.00710"
"1,423.36200","-1.48520","-0.00710"
"1,424.36200","-1.48520","-0.00710"
"1,425.06200","-1.48520","-0.00718"